Workbook

Sheet Form
A1: #VALUE!
B2: Tipping Comp
A4: Name:
A6: Email: | F6: Phone:
A8: Group A | B8: Odds | C8: Rank | D8: Group B | E8: Odds | F8: Rank | G8: Group C | H8: Odds | I8: Rank
A9: Qatar | B9: 251 | D9: England | E9: 7.5 | G9: Argentina | H9: 7.5
A10: Ecuador | B10: 151 | D10: Iran | E10: 501 | G10: Saudi Arabia | H10: 501
A11: Senegal | B11: 91 | D11: USA | E11: 101 | G11: Mexico | H11: 101
A12: Netherlands | B12: 13 | D12: Wales | E12: 151 | G12: Poland | H12: 126
A14: Group D | B14: Odds | C14: Rank | D14: Group E | E14: Odds | F14: Rank | G14: Group F | H14: Odds | I14: Rank
A15: France | B15: 6.5 | D15: Spain | E15: 8.5 | G15: Belgium | H15: 12
A16: Australia | B16: 251 | D16: Costa Rica | E16: 501 | G16: Canada | H16: 201
A17: Denmark | B17: 31 | D17: Germany | E17: 10 | G17: Morocco | H17: 201
A18: Tunisia | B18: 426 | D18: Japan | E18: 251 | G18: Croatia | H18: 46
A20: Group G | B20: Odds | C20: Rank | D20: Group H | E20: Odds | F20: Rank
A21: Brazil | B21: 5 | D21: Portugal | E21: 13
A22: Switzerland | B22: 81 | D22: Ghana | E22: 251
A23: Serbia | B23: 101 | D23: Uruguay | E23: 46
A24: Cameroon | B24: 251 | D24: Korea Rep. | E24: 251
A26: Pick one team and rank them with a star (*). This is likely to be the team you believe will win the World Cup.
A27: Then rank 3 teams in each group from 1 to 3, one group will have rankings for all four teams (with the * included) and the
A28: other 7 groups will only have 3 teams ranked. The way you rank will then score accordingly;
A30: Scoring Points | E30: Multiplier
A31: Win = 5 points | E31: Team ranked 1 will receive 3 times the scored points
A32: Draw = 3 points (inc. penalty games) | E32: Team ranked 2 will receive 2 times the scored points
A33: Lose = 0 points | E33: Team ranked 3 will receive 1 times the scored points
A34: Goals For = 2 points per goal | E34: Team ranked * will receive 5 times the scored points
A35: Goals Against = -1 points per goal
A36: Yellow Card = -1 point per yellow card
A37: Red Card = -5 points per red card
A38: Group Winner = 5 points
A39: Qualify from Group = 2 points
A40: Make Quarter Final = 10 points
A41: Make Semi Final = 15 points
A42: Make Final = 20 points
A43: WC Winner = 30 points

Sheet Results
B1: Win (5) | C1: Draw (3) | D1: Lose (0) | E1: Goals For (2) | F1: Goals Against (-1) | G1: Yellow Cards (-1) | H1: Red Cards (-5) | I1: Group Winner (5) | J1: Qualify (2) | K1: Quarter Final (10) | L1: Semi Final (15) | M1: Final (20) | N1: WC Winner (30) | O1: Points
A2: Group A
A3: Mexico | B3: 1 | E3: 2 | G3: 1 | H3: 1 | O3: =(B3*5)+(C3*3)+(D3*0)+(E3*2)+(F3*-1)+(G3*-1)+(H3*-5)+(I3*5)+(J3*2)+(K3*10)+(L3*15)+(M3*20)+(N3*30) -> 3
A4: South Africa | D4: 1 | F4: 2 | G4: 2 | H4: 2 | O4: =(B4*5)+(C4*3)+(D4*0)+(E4*2)+(F4*-1)+(G4*-1)+(H4*-5)+(I4*5)+(J4*2)+(K4*10)+(L4*15)+(M4*20)+(N4*30) -> -14
A5: Korea Rep. | B5: 1 | E5: 2 | F5: 1 | G5: 1 | O5: =(B5*5)+(C5*3)+(D5*0)+(E5*2)+(F5*-1)+(G5*-1)+(H5*-5)+(I5*5)+(J5*2)+(K5*10)+(L5*15)+(M5*20)+(N5*30) -> 7
A6: Czechia | D6: 1 | E6: 1 | F6: 2 | O6: =(B6*5)+(C6*3)+(D6*0)+(E6*2)+(F6*-1)+(G6*-1)+(H6*-5)+(I6*5)+(J6*2)+(K6*10)+(L6*15)+(M6*20)+(N6*30) -> 0
A7: Group B
A8: Canada | C8: 1 | E8: 1 | F8: 1 | G8: 2 | O8: =(B8*5)+(C8*3)+(D8*0)+(E8*2)+(F8*-1)+(G8*-1)+(H8*-5)+(I8*5)+(J8*2)+(K8*10)+(L8*15)+(M8*20)+(N8*30) -> 2
A9: Bosnia | C9: 1 | E9: 1 | F9: 1 | G9: 3 | O9: =(B9*5)+(C9*3)+(D9*0)+(E9*2)+(F9*-1)+(G9*-1)+(H9*-5)+(I9*5)+(J9*2)+(K9*10)+(L9*15)+(M9*20)+(N9*30) -> 1
A10: Qatar | C10: 1 | E10: 1 | F10: 1 | G10: 2 | O10: =(B10*5)+(C10*3)+(D10*0)+(E10*2)+(F10*-1)+(G10*-1)+(H10*-5)+(I10*5)+(J10*2)+(K10*10)+(L10*15)+(M10*20)+(N10*30) -> 2
A11: Switzerland | C11: 1 | E11: 1 | F11: 1 | G11: 1 | O11: =(B11*5)+(C11*3)+(D11*0)+(E11*2)+(F11*-1)+(G11*-1)+(H11*-5)+(I11*5)+(J11*2)+(K11*10)+(L11*15)+(M11*20)+(N11*30) -> 3
A12: Group C
A13: Brazil | C13: 1 | E13: 1 | F13: 1 | G13: 2 | O13: =(B13*5)+(C13*3)+(D13*0)+(E13*2)+(F13*-1)+(G13*-1)+(H13*-5)+(I13*5)+(J13*2)+(K13*10)+(L13*15)+(M13*20)+(N13*30) -> 2
A14: Morocco | C14: 1 | E14: 1 | F14: 1 | O14: =(B14*5)+(C14*3)+(D14*0)+(E14*2)+(F14*-1)+(G14*-1)+(H14*-5)+(I14*5)+(J14*2)+(K14*10)+(L14*15)+(M14*20)+(N14*30) -> 4
A15: Haiti | D15: 1 | F15: 1 | G15: 1 | O15: =(B15*5)+(C15*3)+(D15*0)+(E15*2)+(F15*-1)+(G15*-1)+(H15*-5)+(I15*5)+(J15*2)+(K15*10)+(L15*15)+(M15*20)+(N15*30) -> -2
A16: Scotland | B16: 1 | E16: 1 | G16: 3 | O16: =(B16*5)+(C16*3)+(D16*0)+(E16*2)+(F16*-1)+(G16*-1)+(H16*-5)+(I16*5)+(J16*2)+(K16*10)+(L16*15)+(M16*20)+(N16*30) -> 4
A17: Group D
A18: USA | B18: 1 | E18: 4 | F18: 1 | G18: 1 | O18: =(B18*5)+(C18*3)+(D18*0)+(E18*2)+(F18*-1)+(G18*-1)+(H18*-5)+(I18*5)+(J18*2)+(K18*10)+(L18*15)+(M18*20)+(N18*30) -> 11
A19: Paraguay | D19: 1 | E19: 1 | F19: 4 | G19: 5 | O19: =(B19*5)+(C19*3)+(D19*0)+(E19*2)+(F19*-1)+(G19*-1)+(H19*-5)+(I19*5)+(J19*2)+(K19*10)+(L19*15)+(M19*20)+(N19*30) -> -7
A20: Australia | B20: 1 | E20: 2 | O20: =(B20*5)+(C20*3)+(D20*0)+(E20*2)+(F20*-1)+(G20*-1)+(H20*-5)+(I20*5)+(J20*2)+(K20*10)+(L20*15)+(M20*20)+(N20*30) -> 9
A21: Turkey | D21: 1 | F21: 2 | G21: 1 | O21: =(B21*5)+(C21*3)+(D21*0)+(E21*2)+(F21*-1)+(G21*-1)+(H21*-5)+(I21*5)+(J21*2)+(K21*10)+(L21*15)+(M21*20)+(N21*30) -> -3
A22: Group E
A23: Germany | B23: 1 | E23: 7 | F23: 1 | O23: =(B23*5)+(C23*3)+(D23*0)+(E23*2)+(F23*-1)+(G23*-1)+(H23*-5)+(I23*5)+(J23*2)+(K23*10)+(L23*15)+(M23*20)+(N23*30) -> 18
A24: Curacao | D24: 1 | E24: 1 | F24: 7 | O24: =(B24*5)+(C24*3)+(D24*0)+(E24*2)+(F24*-1)+(G24*-1)+(H24*-5)+(I24*5)+(J24*2)+(K24*10)+(L24*15)+(M24*20)+(N24*30) -> -5
A25: Ivory Coast | B25: 1 | E25: 1 | G25: 3 | O25: =(B25*5)+(C25*3)+(D25*0)+(E25*2)+(F25*-1)+(G25*-1)+(H25*-5)+(I25*5)+(J25*2)+(K25*10)+(L25*15)+(M25*20)+(N25*30) -> 4
A26: Ecuador | D26: 1 | F26: 1 | G26: 1 | O26: =(B26*5)+(C26*3)+(D26*0)+(E26*2)+(F26*-1)+(G26*-1)+(H26*-5)+(I26*5)+(J26*2)+(K26*10)+(L26*15)+(M26*20)+(N26*30) -> -2
A27: Group F
A28: Netherlands | C28: 1 | E28: 2 | F28: 2 | G28: 3 | O28: =(B28*5)+(C28*3)+(D28*0)+(E28*2)+(F28*-1)+(G28*-1)+(H28*-5)+(I28*5)+(J28*2)+(K28*10)+(L28*15)+(M28*20)+(N28*30) -> 2
A29: Japan | C29: 1 | E29: 2 | F29: 2 | O29: =(B29*5)+(C29*3)+(D29*0)+(E29*2)+(F29*-1)+(G29*-1)+(H29*-5)+(I29*5)+(J29*2)+(K29*10)+(L29*15)+(M29*20)+(N29*30) -> 5
A30: Sweden | B30: 1 | E30: 5 | F30: 1 | O30: =(B30*5)+(C30*3)+(D30*0)+(E30*2)+(F30*-1)+(G30*-1)+(H30*-5)+(I30*5)+(J30*2)+(K30*10)+(L30*15)+(M30*20)+(N30*30) -> 14
A31: Tunisia | D31: 1 | E31: 1 | F31: 5 | G31: 1 | O31: =(B31*5)+(C31*3)+(D31*0)+(E31*2)+(F31*-1)+(G31*-1)+(H31*-5)+(I31*5)+(J31*2)+(K31*10)+(L31*15)+(M31*20)+(N31*30) -> -4
A32: Group G
A33: Belgium | C33: 1 | E33: 1 | F33: 1 | G33: 2 | O33: =(B33*5)+(C33*3)+(D33*0)+(E33*2)+(F33*-1)+(G33*-1)+(H33*-5)+(I33*5)+(J33*2)+(K33*10)+(L33*15)+(M33*20)+(N33*30) -> 2
A34: Egypt | C34: 1 | E34: 1 | F34: 1 | G34: 2 | O34: =(B34*5)+(C34*3)+(D34*0)+(E34*2)+(F34*-1)+(G34*-1)+(H34*-5)+(I34*5)+(J34*2)+(K34*10)+(L34*15)+(M34*20)+(N34*30) -> 2
A35: Iran | C35: 1 | E35: 2 | F35: 2 | G35: 1 | O35: =(B35*5)+(C35*3)+(D35*0)+(E35*2)+(F35*-1)+(G35*-1)+(H35*-5)+(I35*5)+(J35*2)+(K35*10)+(L35*15)+(M35*20)+(N35*30) -> 4
A36: New Zealand | C36: 1 | E36: 2 | F36: 2 | O36: =(B36*5)+(C36*3)+(D36*0)+(E36*2)+(F36*-1)+(G36*-1)+(H36*-5)+(I36*5)+(J36*2)+(K36*10)+(L36*15)+(M36*20)+(N36*30) -> 5
A37: Group H
A38: Spain | C38: 1 | G38: 1 | O38: =(B38*5)+(C38*3)+(D38*0)+(E38*2)+(F38*-1)+(G38*-1)+(H38*-5)+(I38*5)+(J38*2)+(K38*10)+(L38*15)+(M38*20)+(N38*30) -> 2
A39: Cape Verde | C39: 1 | G39: 1 | O39: =(B39*5)+(C39*3)+(D39*0)+(E39*2)+(F39*-1)+(G39*-1)+(H39*-5)+(I39*5)+(J39*2)+(K39*10)+(L39*15)+(M39*20)+(N39*30) -> 2
A40: Saudi Arabia | C40: 1 | E40: 1 | F40: 1 | G40: 1 | O40: =(B40*5)+(C40*3)+(D40*0)+(E40*2)+(F40*-1)+(G40*-1)+(H40*-5)+(I40*5)+(J40*2)+(K40*10)+(L40*15)+(M40*20)+(N40*30) -> 3
...

Sheet Entries
A1: Name: | B1: Lennon Dresner (P) | M1: Total: | N1: =SUM(D3:D6,D8:D11,H3:H6, H8:H11,L3:L6,L8:L11,P3:P6,P8:P11,D13:D16,H13:H16,L13:L16,P13:P16) -> 394 | R1: Name: | S1: Ben Maike (P) | AD1: Total: | AE1: =SUM(U3:U6,U8:U11,Y3:Y6, Y8:Y11,AC3:AC6,AC8:AC11,AG3:AG6,AG8:AG11,U13:U16,Y13:Y16,AC13:AC16,AG13:AG16) -> 363 | AI1: Name: | AJ1: Tyler & Mark Hall | AU1: Total: | AV1: =SUM(AL3:AL6,AL8:AL11,AP3:AP6, AP8:AP11,AT3:AT6,AT8:AT11,AX3:AX6,AX8:AX11,AL13:AL16,AP13:AP16,AT13:AT16,AX13:AX16) -> 373
A2: Group A | B2: Score | C2: Multiplier | D2: Points | E2: Group B | F2: Score | G2: Multiplier | H2: Points | I2: Group C | J2: Score | K2: Multiplier | L2: Points | M2: Group D | N2: Score | O2: Multiplier | P2: Points | R2: Group A | S2: Score | T2: Multiplier | U2: Points | V2: Group B | W2: Score | X2: Multiplier | Y2: Points | Z2: Group C | AA2: Score | AB2: Multiplier | AC2: Points | AD2: Group D | AE2: Score | AF2: Multiplier | AG2: Points | AI2: Group A | AJ2: Score | AK2: Multiplier | AL2: Points | AM2: Group B | AN2: Score | AO2: Multiplier | AP2: Points | AQ2: Group C | AR2: Score | AS2: Multiplier | AT2: Points | AU2: Group D | AV2: Score | AW2: Multiplier | AX2: Points
A3: Mexico | B3: =Results!$O$3 -> 3 | C3: 2 | D3: =B3*C3 -> 6 | E3: Canada | F3: =Results!$O$8 -> 2 | G3: 2 | H3: =F3*G3 -> 4 | I3: Brazil | J3: =Results!$O$13 -> 2 | K3: 5 | L3: =J3*K3 -> 10 | M3: USA | N3: =Results!$O$18 -> 11 | O3: 3 | P3: =N3*O3 -> 33 | R3: Mexico | S3: =Results!$O$3 -> 3 | T3: 3 | U3: =S3*T3 -> 9 | V3: Canada | W3: =Results!$O$8 -> 2 | X3: 3 | Y3: =W3*X3 -> 6 | Z3: Brazil | AA3: =Results!$O$13 -> 2 | AB3: 3 | AC3: =AA3*AB3 -> 6 | AD3: USA | AE3: =Results!$O$18 -> 11 | AF3: 2 | AG3: =AE3*AF3 -> 22 | AI3: Mexico | AJ3: =Results!$O$3 -> 3 | AK3: 3 | AL3: =AJ3*AK3 -> 9 | AM3: Canada | AN3: =Results!$O$8 -> 2 | AO3: 2 | AP3: =AN3*AO3 -> 4 | AQ3: Brazil | AR3: =Results!$O$13 -> 2 | AS3: 3 | AT3: =AR3*AS3 -> 6 | AU3: USA | AV3: =Results!$O$18 -> 11 | AW3: 2 | AX3: =AV3*AW3 -> 22
A4: Sth Africa | B4: =Results!$O$4 -> -14 | D4: =B4*C4 -> 0 | E4: Bosnia | F4: =Results!$O$9 -> 1 | H4: =F4*G4 -> 0 | I4: Morocco | J4: =Results!$O$14 -> 4 | K4: 2 | L4: =J4*K4 -> 8 | M4: Paraguay | N4: =Results!$O$19 -> -7 | P4: =N4*O4 -> 0 | R4: Sth Africa | S4: =Results!$O$4 -> -14 | U4: =S4*T4 -> 0 | V4: Bosnia | W4: =Results!$O$9 -> 1 | Y4: =W4*X4 -> 0 | Z4: Morocco | AA4: =Results!$O$14 -> 4 | AB4: 2 | AC4: =AA4*AB4 -> 8 | AD4: Paraguay | AE4: =Results!$O$19 -> -7 | AF4: 3 | AG4: =AE4*AF4 -> -21 | AI4: Sth Africa | AJ4: =Results!$O$4 -> -14 | AL4: =AJ4*AK4 -> 0 | AM4: Bosnia | AN4: =Results!$O$9 -> 1 | AO4: 1 | AP4: =AN4*AO4 -> 1 | AQ4: Morocco | AR4: =Results!$O$14 -> 4 | AS4: 1 | AT4: =AR4*AS4 -> 4 | AU4: Paraguay | AV4: =Results!$O$19 -> -7 | AX4: =AV4*AW4 -> 0
A5: Korea Rep | B5: =Results!$O$5 -> 7 | C5: 3 | D5: =B5*C5 -> 21 | E5: Qatar | F5: =Results!$O$10 -> 2 | G5: 1 | H5: =F5*G5 -> 2 | I5: Haiti | J5: =Results!$O$15 -> -2 | K5: 1 | L5: =J5*K5 -> -2 | M5: Australia | N5: =Results!$O$20 -> 9 | O5: 2 | P5: =N5*O5 -> 18 | R5: Korea Rep | S5: =Results!$O$5 -> 7 | T5: 1 | U5: =S5*T5 -> 7 | V5: Qatar | W5: =Results!$O$10 -> 2 | X5: 1 | Y5: =W5*X5 -> 2 | Z5: Haiti | AA5: =Results!$O$15 -> -2 | AC5: =AA5*AB5 -> 0 | AD5: Australia | AE5: =Results!$O$20 -> 9 | AG5: =AE5*AF5 -> 0 | AI5: Korea Rep | AJ5: =Results!$O$5 -> 7 | AK5: 2 | AL5: =AJ5*AK5 -> 14 | AM5: Qatar | AN5: =Results!$O$10 -> 2 | AP5: =AN5*AO5 -> 0 | AQ5: Haiti | AR5: =Results!$O$15 -> -2 | AT5: =AR5*AS5 -> 0 | AU5: Australia | AV5: =Results!$O$20 -> 9 | AW5: 1 | AX5: =AV5*AW5 -> 9
A6: Czechia | B6: =Results!$O$6 -> 0 | C6: 1 | D6: =B6*C6 -> 0 | E6: Switzerland | F6: =Results!$O$11 -> 3 | G6: 3 | H6: =F6*G6 -> 9 | I6: Scotland | J6: =Results!$O$16 -> 4 | K6: 3 | L6: =J6*K6 -> 12 | M6: Turkey | N6: =Results!$O$21 -> -3 | O6: 1 | P6: =N6*O6 -> -3 | R6: Czechia | S6: =Results!$O$6 -> 0 | T6: 2 | U6: =S6*T6 -> 0 | V6: Switzerland | W6: =Results!$O$11 -> 3 | X6: 2 | Y6: =W6*X6 -> 6 | Z6: Scotland | AA6: =Results!$O$16 -> 4 | AB6: 1 | AC6: =AA6*AB6 -> 4 | AD6: Turkey | AE6: =Results!$O$21 -> -3 | AF6: 1 | AG6: =AE6*AF6 -> -3 | AI6: Czechia | AJ6: =Results!$O$6 -> 0 | AK6: 1 | AL6: =AJ6*AK6 -> 0 | AM6: Switzerland | AN6: =Results!$O$11 -> 3 | AO6: 3 | AP6: =AN6*AO6 -> 9 | AQ6: Scotland | AR6: =Results!$O$16 -> 4 | AS6: 2 | AT6: =AR6*AS6 -> 8 | AU6: Turkey | AV6: =Results!$O$21 -> -3 | AW6: 3 | AX6: =AV6*AW6 -> -9
A7: Group E | B7: Score | C7: Multiplier | D7: Points | E7: Group F | F7: Score | G7: Multiplier | H7: Points | I7: Group G | J7: Score | K7: Multiplier | L7: Points | M7: Group H | N7: Score | O7: Multiplier | P7: Points | R7: Group E | S7: Score | T7: Multiplier | U7: Points | V7: Group F | W7: Score | X7: Multiplier | Y7: Points | Z7: Group G | AA7: Score | AB7: Multiplier | AC7: Points | AD7: Group H | AE7: Score | AF7: Multiplier | AG7: Points | AI7: Group E | AJ7: Score | AK7: Multiplier | AL7: Points | AM7: Group F | AN7: Score | AO7: Multiplier | AP7: Points | AQ7: Group G | AR7: Score | AS7: Multiplier | AT7: Points | AU7: Group H | AV7: Score | AW7: Multiplier | AX7: Points
A8: Germany | B8: =Results!$O$23 -> 18 | C8: 3 | D8: =B8*C8 -> 54 | E8: Netherlands | F8: =Results!$O$28 -> 2 | G8: 3 | H8: =F8*G8 -> 6 | I8: Belgium | J8: =Results!$O$33 -> 2 | K8: 3 | L8: =J8*K8 -> 6 | M8: Spain | N8: =Results!$O$38 -> 2 | O8: 3 | P8: =N8*O8 -> 6 | R8: Germany | S8: =Results!$O$23 -> 18 | T8: 3 | U8: =S8*T8 -> 54 | V8: Netherlands | W8: =Results!$O$28 -> 2 | X8: 3 | Y8: =W8*X8 -> 6 | Z8: Belgium | AA8: =Results!$O$33 -> 2 | AB8: 3 | AC8: =AA8*AB8 -> 6 | AD8: Spain | AE8: =Results!$O$38 -> 2 | AF8: 3 | AG8: =AE8*AF8 -> 6 | AI8: Germany | AJ8: =Results!$O$23 -> 18 | AK8: 3 | AL8: =AJ8*AK8 -> 54 | AM8: Netherlands | AN8: =Results!$O$28 -> 2 | AO8: 3 | AP8: =AN8*AO8 -> 6 | AQ8: Belgium | AR8: =Results!$O$33 -> 2 | AS8: 3 | AT8: =AR8*AS8 -> 6 | AU8: Spain | AV8: =Results!$O$38 -> 2 | AW8: 3 | AX8: =AV8*AW8 -> 6
A9: Curacao | B9: =Results!$O$24 -> -5 | D9: =B9*C9 -> 0 | E9: Japan | F9: =Results!$O$29 -> 5 | G9: 1 | H9: =F9*G9 -> 5 | I9: Egypt | J9: =Results!$O$34 -> 2 | K9: 2 | L9: =J9*K9 -> 4 | M9: Cape Verde | N9: =Results!$O$39 -> 2 | P9: =N9*O9 -> 0 | R9: Curacao | S9: =Results!$O$24 -> -5 | U9: =S9*T9 -> 0 | V9: Japan | W9: =Results!$O$29 -> 5 | X9: 1 | Y9: =W9*X9 -> 5 | Z9: Egypt | AA9: =Results!$O$34 -> 2 | AB9: 2 | AC9: =AA9*AB9 -> 4 | AD9: Cape Verde | AE9: =Results!$O$39 -> 2 | AG9: =AE9*AF9 -> 0 | AI9: Curacao | AJ9: =Results!$O$24 -> -5 | AL9: =AJ9*AK9 -> 0 | AM9: Japan | AN9: =Results!$O$29 -> 5 | AO9: 2 | AP9: =AN9*AO9 -> 10 | AQ9: Egypt | AR9: =Results!$O$34 -> 2 | AS9: 2 | AT9: =AR9*AS9 -> 4 | AU9: Cape Verde | AV9: =Results!$O$39 -> 2 | AX9: =AV9*AW9 -> 0
A10: Ivory Coast | B10: =Results!$O$25 -> 4 | C10: 1 | D10: =B10*C10 -> 4 | E10: Sweden | F10: =Results!$O$30 -> 14 | G10: 2 | H10: =F10*G10 -> 28 | I10: Iran | J10: =Results!$O$35 -> 4 | K10: 1 | L10: =J10*K10 -> 4 | M10: Saudi Arabia | N10: =Results!$O$40 -> 3 | O10: 1 | P10: =N10*O10 -> 3 | R10: Ivory Coast | S10: =Results!$O$25 -> 4 | T10: 1 | U10: =S10*T10 -> 4 | V10: Sweden | W10: =Results!$O$30 -> 14 | X10: 2 | Y10: =W10*X10 -> 28 | Z10: Iran | AA10: =Results!$O$35 -> 4 | AB10: 1 | AC10: =AA10*AB10 -> 4 | AD10: Saudi Arabia | AE10: =Results!$O$40 -> 3 | AF10: 1 | AG10: =AE10*AF10 -> 3 | AI10: Ivory Coast | AJ10: =Results!$O$25 -> 4 | AK10: 1 | AL10: =AJ10*AK10 -> 4 | AM10: Sweden | AN10: =Results!$O$30 -> 14 | AO10: 1 | AP10: =AN10*AO10 -> 14 | AQ10: Iran | AR10: =Results!$O$35 -> 4 | AT10: =AR10*AS10 -> 0 | AU10: Saudi Arabia | AV10: =Results!$O$40 -> 3 | AW10: 1 | AX10: =AV10*AW10 -> 3
A11: Ecuador | B11: =Results!$O$26 -> -2 | C11: 2 | D11: =B11*C11 -> -4 | E11: Tunisia | F11: =Results!$O$31 -> -4 | H11: =F11*G11 -> 0 | I11: New Zealand | J11: =Results!$O$36 -> 5 | L11: =J11*K11 -> 0 | M11: Uruguay | N11: =Results!$O$41 -> 4 | O11: 2 | P11: =N11*O11 -> 8 | R11: Ecuador | S11: =Results!$O$26 -> -2 | T11: 2 | U11: =S11*T11 -> -4 | V11: Tunisia | W11: =Results!$O$31 -> -4 | Y11: =W11*X11 -> 0 | Z11: New Zealand | AA11: =Results!$O$36 -> 5 | AC11: =AA11*AB11 -> 0 | AD11: Uruguay | AE11: =Results!$O$41 -> 4 | AF11: 2 | AG11: =AE11*AF11 -> 8 | AI11: Ecuador | AJ11: =Results!$O$26 -> -2 | AK11: 2 | AL11: =AJ11*AK11 -> -4 | AM11: Tunisia | AN11: =Results!$O$31 -> -4 | AP11: =AN11*AO11 -> 0 | AQ11: New Zealand | AR11: =Results!$O$36 -> 5 | AS11: 1 | AT11: =AR11*AS11 -> 5 | AU11: Uruguay | AV11: =Results!$O$41 -> 4 | AW11: 2 | AX11: =AV11*AW11 -> 8
A12: Group I | B12: Score | C12: Multiplier | D12: Points | E12: Group J | F12: Score | G12: Multiplier | H12: Points | I12: Group K | J12: Score | K12: Multiplier | L12: Points | M12: Group L | N12: Score | O12: Multiplier | P12: Points | R12: Group I | S12: Score | T12: Multiplier | U12: Points | V12: Group J | W12: Score | X12: Multiplier | Y12: Points | Z12: Group K | AA12: Score | AB12: Multiplier | AC12: Points | AD12: Group L | AE12: Score | AF12: Multiplier | AG12: Points | AI12: Group I | AJ12: Score | AK12: Multiplier | AL12: Points | AM12: Group J | AN12: Score | AO12: Multiplier | AP12: Points | AQ12: Group K | AR12: Score | AS12: Multiplier | AT12: Points | AU12: Group L | AV12: Score | AW12: Multiplier | AX12: Points
A13: France | B13: =Results!$O$43 -> 10 | C13: 3 | D13: =B13*C13 -> 30 | E13: Argentina | F13: =Results!$O$48 -> 11 | G13: 3 | H13: =F13*G13 -> 33 | I13: Portugal | J13: =Results!$O$53 -> 1 | K13: 3 | L13: =J13*K13 -> 3 | M13: England | N13: =Results!$O$58 -> 11 | O13: 3 | P13: =N13*O13 -> 33 | R13: France | S13: =Results!$O$43 -> 10 | T13: 5 | U13: =S13*T13 -> 50 | V13: Argentina | W13: =Results!$O$48 -> 11 | X13: 3 | Y13: =W13*X13 -> 33 | Z13: Portugal | AA13: =Results!$O$53 -> 1 | AB13: 3 | AC13: =AA13*AB13 -> 3 | AD13: England | AE13: =Results!$O$58 -> 11 | AF13: 3 | AG13: =AE13*AF13 -> 33 | AI13: France | AJ13: =Results!$O$43 -> 10 | AK13: 5 | AL13: =AJ13*AK13 -> 50 | AM13: Argentina | AN13: =Results!$O$48 -> 11 | AO13: 3 | AP13: =AN13*AO13 -> 33 | AQ13: Portugal | AR13: =Results!$O$53 -> 1 | AS13: 3 | AT13: =AR13*AS13 -> 3 | AU13: England | AV13: =Results!$O$58 -> 11 | AW13: 3 | AX13: =AV13*AW13 -> 33
A14: Senegal | B14: =Results!$O$44 -> -1 | C14: 1 | D14: =B14*C14 -> -1 | E14: Algeria | F14: =Results!$O$49 -> -3 | G14: 2 | H14: =F14*G14 -> -6 | I14: Congo | J14: =Results!$O$54 -> 3 | K14: 1 | L14: =J14*K14 -> 3 | M14: Croatia | N14: =Results!$O$59 -> 0 | O14: 2 | P14: =N14*O14 -> 0 | R14: Senegal | S14: =Results!$O$44 -> -1 | T14: 2 | U14: =S14*T14 -> -2 | V14: Algeria | W14: =Results!$O$49 -> -3 | X14: 1 | Y14: =W14*X14 -> -3 | Z14: Congo | AA14: =Results!$O$54 -> 3 | AC14: =AA14*AB14 -> 0 | AD14: Croatia | AE14: =Results!$O$59 -> 0 | AF14: 1 | AG14: =AE14*AF14 -> 0 | AI14: Senegal | AJ14: =Results!$O$44 -> -1 | AK14: 2 | AL14: =AJ14*AK14 -> -2 | AM14: Algeria | AN14: =Results!$O$49 -> -3 | AO14: 2 | AP14: =AN14*AO14 -> -6 | AQ14: Congo | AR14: =Results!$O$54 -> 3 | AS14: 1 | AT14: =AR14*AS14 -> 3 | AU14: Croatia | AV14: =Results!$O$59 -> 0 | AW14: 2 | AX14: =AV14*AW14 -> 0
A15: Iraq | B15: =Results!$O$45 -> -3 | D15: =B15*C15 -> 0 | E15: Austria | F15: =Results!$O$50 -> 9 | G15: 1 | H15: =F15*G15 -> 9 | I15: Uzebekistan | J15: =Results!$O$55 -> -2 | L15: =J15*K15 -> 0 | M15: Ghana | N15: =Results!$O$60 -> 6 | O15: 1 | P15: =N15*O15 -> 6 | R15: Iraq | S15: =Results!$O$45 -> -3 | T15: 1 | U15: =S15*T15 -> -3 | V15: Austria | W15: =Results!$O$50 -> 9 | X15: 2 | Y15: =W15*X15 -> 18 | Z15: Uzebekistan | AA15: =Results!$O$55 -> -2 | AB15: 1 | AC15: =AA15*AB15 -> -2 | AD15: Ghana | AE15: =Results!$O$60 -> 6 | AF15: 2 | AG15: =AE15*AF15 -> 12 | AI15: Iraq | AJ15: =Results!$O$45 -> -3 | AK15: 1 | AL15: =AJ15*AK15 -> -3 | AM15: Austria | AN15: =Results!$O$50 -> 9 | AO15: 1 | AP15: =AN15*AO15 -> 9 | AQ15: Uzebekistan | AR15: =Results!$O$55 -> -2 | AT15: =AR15*AS15 -> 0 | AU15: Ghana | AV15: =Results!$O$60 -> 6 | AW15: 1 | AX15: =AV15*AW15 -> 6
A16: Norway | B16: =Results!$O$46 -> 12 | C16: 2 | D16: =B16*C16 -> 24 | E16: Jordan | F16: =Results!$O$51 -> -1 | H16: =F16*G16 -> 0 | I16: Colombia | J16: =Results!$O$56 -> 9 | K16: 2 | L16: =J16*K16 -> 18 | M16: Panama | N16: =Results!$O$61 -> -3 | P16: =N16*O16 -> 0 | R16: Norway | S16: =Results!$O$46 -> 12 | T16: 3 | U16: =S16*T16 -> 36 | V16: Jordan | W16: =Results!$O$51 -> -1 | Y16: =W16*X16 -> 0 | Z16: Colombia | AA16: =Results!$O$56 -> 9 | AB16: 2 | AC16: =AA16*AB16 -> 18 | AD16: Panama | AE16: =Results!$O$61 -> -3 | AG16: =AE16*AF16 -> 0 | AI16: Norway | AJ16: =Results!$O$46 -> 12 | AK16: 3 | AL16: =AJ16*AK16 -> 36 | AM16: Jordan | AN16: =Results!$O$51 -> -1 | AP16: =AN16*AO16 -> 0 | AQ16: Colombia | AR16: =Results!$O$56 -> 9 | AS16: 2 | AT16: =AR16*AS16 -> 18 | AU16: Panama | AV16: =Results!$O$61 -> -3 | AX16: =AV16*AW16 -> 0
A18: Name: | B18: Nash Dresner (P) | M18: Total: | N18: =SUM(D20:D23,D25:D28,H20:H23,H25:H28,L20:L23,L25:L28,P20:P23,P25:P28,D30:D33,H30:H33,L30:L33,P30:P33) -> 403 | R18: Name: | S18: Max Maike (P) | AD18: Total: | AE18: =SUM(U20:U23,U25:U28,Y20:Y23, Y25:Y28,AC20:AC23,AC25:AC28,AG20:AG23,AG25:AG28,U30:U33,Y30:Y33,AC30:AC33,AG30:AG33) -> 378 | AI18: Name: | AJ18: Gavin Fuchs (P) | AU18: Total: | AV18: =SUM(AL20:AL23,AL25:AL28,AP20:AP23, AP25:AP28,AT20:AT23,AT25:AT28,AX20:AX23,AX25:AX28,AL30:AL33,AP30:AP33,AT30:AT33,AX30:AX33) -> 382
A19: Group A | B19: Score | C19: Multiplier | D19: Points | E19: Group B | F19: Score | G19: Multiplier | H19: Points | I19: Group C | J19: Score | K19: Multiplier | L19: Points | M19: Group D | N19: Score | O19: Multiplier | P19: Points | R19: Group A | S19: Score | T19: Multiplier | U19: Points | V19: Group B | W19: Score | X19: Multiplier | Y19: Points | Z19: Group C | AA19: Score | AB19: Multiplier | AC19: Points | AD19: Group D | AE19: Score | AF19: Multiplier | AG19: Points | AI19: Group A | AJ19: Score | AK19: Multiplier | AL19: Points | AM19: Group B | AN19: Score | AO19: Multiplier | AP19: Points | AQ19: Group C | AR19: Score | AS19: Multiplier | AT19: Points | AU19: Group D | AV19: Score | AW19: Multiplier | AX19: Points
A20: Mexico | B20: =Results!$O$3 -> 3 | C20: 3 | D20: =B20*C20 -> 9 | E20: Canada | F20: =Results!$O$8 -> 2 | G20: 2 | H20: =F20*G20 -> 4 | I20: Brazil | J20: =Results!$O$13 -> 2 | K20: 3 | L20: =J20*K20 -> 6 | M20: USA | N20: =Results!$O$18 -> 11 | O20: 3 | P20: =N20*O20 -> 33 | R20: Mexico | S20: =Results!$O$3 -> 3 | T20: 2 | U20: =S20*T20 -> 6 | V20: Canada | W20: =Results!$O$8 -> 2 | X20: 3 | Y20: =W20*X20 -> 6 | Z20: Brazil | AA20: =Results!$O$13 -> 2 | AB20: 3 | AC20: =AA20*AB20 -> 6 | AD20: USA | AE20: =Results!$O$18 -> 11 | AF20: 1 | AG20: =AE20*AF20 -> 11 | AI20: Mexico | AJ20: =Results!$O$3 -> 3 | AK20: 3 | AL20: =AJ20*AK20 -> 9 | AM20: Canada | AN20: =Results!$O$8 -> 2 | AO20: 2 | AP20: =AN20*AO20 -> 4 | AQ20: Brazil | AR20: =Results!$O$13 -> 2 | AS20: 3 | AT20: =AR20*AS20 -> 6 | AU20: USA | AV20: =Results!$O$18 -> 11 | AW20: 3 | AX20: =AV20*AW20 -> 33
A21: Sth Africa | B21: =Results!$O$4 -> -14 | D21: =B21*C21 -> 0 | E21: Bosnia | F21: =Results!$O$9 -> 1 | G21: 1 | H21: =F21*G21 -> 1 | I21: Morocco | J21: =Results!$O$14 -> 4 | K21: 2 | L21: =J21*K21 -> 8 | M21: Paraguay | N21: =Results!$O$19 -> -7 | P21: =N21*O21 -> 0 | R21: Sth Africa | S21: =Results!$O$4 -> -14 | T21: 1 | U21: =S21*T21 -> -14 | V21: Bosnia | W21: =Results!$O$9 -> 1 | Y21: =W21*X21 -> 0 | Z21: Morocco | AA21: =Results!$O$14 -> 4 | AB21: 1 | AC21: =AA21*AB21 -> 4 | AD21: Paraguay | AE21: =Results!$O$19 -> -7 | AG21: =AE21*AF21 -> 0 | AI21: Sth Africa | AJ21: =Results!$O$4 -> -14 | AL21: =AJ21*AK21 -> 0 | AM21: Bosnia | AN21: =Results!$O$9 -> 1 | AP21: =AN21*AO21 -> 0 | AQ21: Morocco | AR21: =Results!$O$14 -> 4 | AS21: 2 | AT21: =AR21*AS21 -> 8 | AU21: Paraguay | AV21: =Results!$O$19 -> -7 | AW21: 1 | AX21: =AV21*AW21 -> -7
A22: Korea Rep | B22: =Results!$O$5 -> 7 | C22: 2 | D22: =B22*C22 -> 14 | E22: Qatar | F22: =Results!$O$10 -> 2 | H22: =F22*G22 -> 0 | I22: Haiti | J22: =Results!$O$15 -> -2 | L22: =J22*K22 -> 0 | M22: Australia | N22: =Results!$O$20 -> 9 | O22: 1 | P22: =N22*O22 -> 9 | R22: Korea Rep | S22: =Results!$O$5 -> 7 | U22: =S22*T22 -> 0 | V22: Qatar | W22: =Results!$O$10 -> 2 | X22: 1 | Y22: =W22*X22 -> 2 | Z22: Haiti | AA22: =Results!$O$15 -> -2 | AC22: =AA22*AB22 -> 0 | AD22: Australia | AE22: =Results!$O$20 -> 9 | AF22: 3 | AG22: =AE22*AF22 -> 27 | AI22: Korea Rep | AJ22: =Results!$O$5 -> 7 | AK22: 2 | AL22: =AJ22*AK22 -> 14 | AM22: Qatar | AN22: =Results!$O$10 -> 2 | AO22: 1 | AP22: =AN22*AO22 -> 2 | AQ22: Haiti | AR22: =Results!$O$15 -> -2 | AT22: =AR22*AS22 -> 0 | AU22: Australia | AV22: =Results!$O$20 -> 9 | AX22: =AV22*AW22 -> 0
A23: Czechia | B23: =Results!$O$6 -> 0 | C23: 1 | D23: =B23*C23 -> 0 | E23: Switzerland | F23: =Results!$O$11 -> 3 | G23: 3 | H23: =F23*G23 -> 9 | I23: Scotland | J23: =Results!$O$16 -> 4 | K23: 1 | L23: =J23*K23 -> 4 | M23: Turkey | N23: =Results!$O$21 -> -3 | O23: 2 | P23: =N23*O23 -> -6 | R23: Czechia | S23: =Results!$O$6 -> 0 | T23: 3 | U23: =S23*T23 -> 0 | V23: Switzerland | W23: =Results!$O$11 -> 3 | X23: 2 | Y23: =W23*X23 -> 6 | Z23: Scotland | AA23: =Results!$O$16 -> 4 | AB23: 2 | AC23: =AA23*AB23 -> 8 | AD23: Turkey | AE23: =Results!$O$21 -> -3 | AF23: 2 | AG23: =AE23*AF23 -> -6 | AI23: Czechia | AJ23: =Results!$O$6 -> 0 | AK23: 1 | AL23: =AJ23*AK23 -> 0 | AM23: Switzerland | AN23: =Results!$O$11 -> 3 | AO23: 3 | AP23: =AN23*AO23 -> 9 | AQ23: Scotland | AR23: =Results!$O$16 -> 4 | AS23: 1 | AT23: =AR23*AS23 -> 4 | AU23: Turkey | AV23: =Results!$O$21 -> -3 | AW23: 2 | AX23: =AV23*AW23 -> -6
A24: Group E | B24: Score | C24: Multiplier | D24: Points | E24: Group F | F24: Score | G24: Multiplier | H24: Points | I24: Group G | J24: Score | K24: Multiplier | L24: Points | M24: Group H | N24: Score | O24: Multiplier | P24: Points | R24: Group E | S24: Score | T24: Multiplier | U24: Points | V24: Group F | W24: Score | X24: Multiplier | Y24: Points | Z24: Group G | AA24: Score | AB24: Multiplier | AC24: Points | AD24: Group H | AE24: Score | AF24: Multiplier | AG24: Points | AI24: Group E | AJ24: Score | AK24: Multiplier | AL24: Points | AM24: Group F | AN24: Score | AO24: Multiplier | AP24: Points | AQ24: Group G | AR24: Score | AS24: Multiplier | AT24: Points | AU24: Group H | AV24: Score | AW24: Multiplier | AX24: Points
A25: Germany | B25: =Results!$O$23 -> 18 | C25: 3 | D25: =B25*C25 -> 54 | E25: Netherlands | F25: =Results!$O$28 -> 2 | G25: 2 | H25: =F25*G25 -> 4 | I25: Belgium | J25: =Results!$O$33 -> 2 | K25: 3 | L25: =J25*K25 -> 6 | M25: Spain | N25: =Results!$O$38 -> 2 | O25: 3 | P25: =N25*O25 -> 6 | R25: Germany | S25: =Results!$O$23 -> 18 | T25: 5 | U25: =S25*T25 -> 90 | V25: Netherlands | W25: =Results!$O$28 -> 2 | X25: 3 | Y25: =W25*X25 -> 6 | Z25: Belgium | AA25: =Results!$O$33 -> 2 | AB25: 3 | AC25: =AA25*AB25 -> 6 | AD25: Spain | AE25: =Results!$O$38 -> 2 | AF25: 3 | AG25: =AE25*AF25 -> 6 | AI25: Germany | AJ25: =Results!$O$23 -> 18 | AK25: 3 | AL25: =AJ25*AK25 -> 54 | AM25: Netherlands | AN25: =Results!$O$28 -> 2 | AO25: 3 | AP25: =AN25*AO25 -> 6 | AQ25: Belgium | AR25: =Results!$O$33 -> 2 | AS25: 3 | AT25: =AR25*AS25 -> 6 | AU25: Spain | AV25: =Results!$O$38 -> 2 | AW25: 3 | AX25: =AV25*AW25 -> 6
A26: Curacao | B26: =Results!$O$24 -> -5 | D26: =B26*C26 -> 0 | E26: Japan | F26: =Results!$O$29 -> 5 | G26: 3 | H26: =F26*G26 -> 15 | I26: Egypt | J26: =Results!$O$34 -> 2 | K26: 2 | L26: =J26*K26 -> 4 | M26: Cape Verde | N26: =Results!$O$39 -> 2 | P26: =N26*O26 -> 0 | R26: Curacao | S26: =Results!$O$24 -> -5 | T26: 1 | U26: =S26*T26 -> -5 | V26: Japan | W26: =Results!$O$29 -> 5 | X26: 1 | Y26: =W26*X26 -> 5 | Z26: Egypt | AA26: =Results!$O$34 -> 2 | AB26: 2 | AC26: =AA26*AB26 -> 4 | AD26: Cape Verde | AE26: =Results!$O$39 -> 2 | AG26: =AE26*AF26 -> 0 | AI26: Curacao | AJ26: =Results!$O$24 -> -5 | AL26: =AJ26*AK26 -> 0 | AM26: Japan | AN26: =Results!$O$29 -> 5 | AO26: 2 | AP26: =AN26*AO26 -> 10 | AQ26: Egypt | AR26: =Results!$O$34 -> 2 | AS26: 2 | AT26: =AR26*AS26 -> 4 | AU26: Cape Verde | AV26: =Results!$O$39 -> 2 | AX26: =AV26*AW26 -> 0
A27: Ivory Coast | B27: =Results!$O$25 -> 4 | C27: 1 | D27: =B27*C27 -> 4 | E27: Sweden | F27: =Results!$O$30 -> 14 | G27: 1 | H27: =F27*G27 -> 14 | I27: Iran | J27: =Results!$O$35 -> 4 | L27: =J27*K27 -> 0 | M27: Saudi Arabia | N27: =Results!$O$40 -> 3 | O27: 1 | P27: =N27*O27 -> 3 | R27: Ivory Coast | S27: =Results!$O$25 -> 4 | T27: 2 | U27: =S27*T27 -> 8 | V27: Sweden | W27: =Results!$O$30 -> 14 | X27: 2 | Y27: =W27*X27 -> 28 | Z27: Iran | AA27: =Results!$O$35 -> 4 | AC27: =AA27*AB27 -> 0 | AD27: Saudi Arabia | AE27: =Results!$O$40 -> 3 | AF27: 1 | AG27: =AE27*AF27 -> 3 | AI27: Ivory Coast | AJ27: =Results!$O$25 -> 4 | AK27: 2 | AL27: =AJ27*AK27 -> 8 | AM27: Sweden | AN27: =Results!$O$30 -> 14 | AO27: 1 | AP27: =AN27*AO27 -> 14 | AQ27: Iran | AR27: =Results!$O$35 -> 4 | AT27: =AR27*AS27 -> 0 | AU27: Saudi Arabia | AV27: =Results!$O$40 -> 3 | AW27: 1 | AX27: =AV27*AW27 -> 3
A28: Ecuador | B28: =Results!$O$26 -> -2 | C28: 2 | D28: =B28*C28 -> -4 | E28: Tunisia | F28: =Results!$O$31 -> -4 | H28: =F28*G28 -> 0 | I28: New Zealand | J28: =Results!$O$36 -> 5 | K28: 1 | L28: =J28*K28 -> 5 | M28: Uruguay | N28: =Results!$O$41 -> 4 | O28: 2 | P28: =N28*O28 -> 8 | R28: Ecuador | S28: =Results!$O$26 -> -2 | T28: 3 | U28: =S28*T28 -> -6 | V28: Tunisia | W28: =Results!$O$31 -> -4 | Y28: =W28*X28 -> 0 | Z28: New Zealand | AA28: =Results!$O$36 -> 5 | AB28: 1 | AC28: =AA28*AB28 -> 5 | AD28: Uruguay | AE28: =Results!$O$41 -> 4 | AF28: 2 | AG28: =AE28*AF28 -> 8 | AI28: Ecuador | AJ28: =Results!$O$26 -> -2 | AK28: 1 | AL28: =AJ28*AK28 -> -2 | AM28: Tunisia | AN28: =Results!$O$31 -> -4 | AP28: =AN28*AO28 -> 0 | AQ28: New Zealand | AR28: =Results!$O$36 -> 5 | AS28: 1 | AT28: =AR28*AS28 -> 5 | AU28: Uruguay | AV28: =Results!$O$41 -> 4 | AW28: 2 | AX28: =AV28*AW28 -> 8
A29: Group I | B29: Score | C29: Multiplier | D29: Points | E29: Group J | F29: Score | G29: Multiplier | H29: Points | I29: Group K | J29: Score | K29: Multiplier | L29: Points | M29: Group L | N29: Score | O29: Multiplier | P29: Points | R29: Group I | S29: Score | T29: Multiplier | U29: Points | V29: Group J | W29: Score | X29: Multiplier | Y29: Points | Z29: Group K | AA29: Score | AB29: Multiplier | AC29: Points | AD29: Group L | AE29: Score | AF29: Multiplier | AG29: Points | AI29: Group I | AJ29: Score | AK29: Multiplier | AL29: Points | AM29: Group J | AN29: Score | AO29: Multiplier | AP29: Points | AQ29: Group K | AR29: Score | AS29: Multiplier | AT29: Points | AU29: Group L | AV29: Score | AW29: Multiplier | AX29: Points
A30: France | B30: =Results!$O$43 -> 10 | C30: 2 | D30: =B30*C30 -> 20 | E30: Argentina | F30: =Results!$O$48 -> 11 | G30: 3 | H30: =F30*G30 -> 33 | I30: Portugal | J30: =Results!$O$53 -> 1 | K30: 3 | L30: =J30*K30 -> 3 | M30: England | N30: =Results!$O$58 -> 11 | O30: 5 | P30: =N30*O30 -> 55 | R30: France | S30: =Results!$O$43 -> 10 | T30: 3 | U30: =S30*T30 -> 30 | V30: Argentina | W30: =Results!$O$48 -> 11 | X30: 3 | Y30: =W30*X30 -> 33 | Z30: Portugal | AA30: =Results!$O$53 -> 1 | AB30: 3 | AC30: =AA30*AB30 -> 3 | AD30: England | AE30: =Results!$O$58 -> 11 | AF30: 3 | AG30: =AE30*AF30 -> 33 | AI30: France | AJ30: =Results!$O$43 -> 10 | AK30: 3 | AL30: =AJ30*AK30 -> 30 | AM30: Argentina | AN30: =Results!$O$48 -> 11 | AO30: 3 | AP30: =AN30*AO30 -> 33 | AQ30: Portugal | AR30: =Results!$O$53 -> 1 | AS30: 3 | AT30: =AR30*AS30 -> 3 | AU30: England | AV30: =Results!$O$58 -> 11 | AW30: 5 | AX30: =AV30*AW30 -> 55
A31: Senegal | B31: =Results!$O$44 -> -1 | C31: 1 | D31: =B31*C31 -> -1 | E31: Algeria | F31: =Results!$O$49 -> -3 | H31: =F31*G31 -> 0 | I31: Congo | J31: =Results!$O$54 -> 3 | K31: 1 | L31: =J31*K31 -> 3 | M31: Croatia | N31: =Results!$O$59 -> 0 | O31: 3 | P31: =N31*O31 -> 0 | R31: Senegal | S31: =Results!$O$44 -> -1 | U31: =S31*T31 -> 0 | V31: Algeria | W31: =Results!$O$49 -> -3 | Y31: =W31*X31 -> 0 | Z31: Congo | AA31: =Results!$O$54 -> 3 | AB31: 1 | AC31: =AA31*AB31 -> 3 | AD31: Croatia | AE31: =Results!$O$59 -> 0 | AF31: 2 | AG31: =AE31*AF31 -> 0 | AI31: Senegal | AJ31: =Results!$O$44 -> -1 | AK31: 1 | AL31: =AJ31*AK31 -> -1 | AM31: Algeria | AN31: =Results!$O$49 -> -3 | AO31: 1 | AP31: =AN31*AO31 -> -3 | AQ31: Congo | AR31: =Results!$O$54 -> 3 | AT31: =AR31*AS31 -> 0 | AU31: Croatia | AV31: =Results!$O$59 -> 0 | AW31: 3 | AX31: =AV31*AW31 -> 0
A32: Iraq | B32: =Results!$O$45 -> -3 | D32: =B32*C32 -> 0 | E32: Austria | F32: =Results!$O$50 -> 9 | G32: 2 | H32: =F32*G32 -> 18 | I32: Uzebekistan | J32: =Results!$O$55 -> -2 | L32: =J32*K32 -> 0 | M32: Ghana | N32: =Results!$O$60 -> 6 | O32: 2 | P32: =N32*O32 -> 12 | R32: Iraq | S32: =Results!$O$45 -> -3 | T32: 1 | U32: =S32*T32 -> -3 | V32: Austria | W32: =Results!$O$50 -> 9 | X32: 2 | Y32: =W32*X32 -> 18 | Z32: Uzebekistan | AA32: =Results!$O$55 -> -2 | AC32: =AA32*AB32 -> 0 | AD32: Ghana | AE32: =Results!$O$60 -> 6 | AF32: 1 | AG32: =AE32*AF32 -> 6 | AI32: Iraq | AJ32: =Results!$O$45 -> -3 | AL32: =AJ32*AK32 -> 0 | AM32: Austria | AN32: =Results!$O$50 -> 9 | AO32: 2 | AP32: =AN32*AO32 -> 18 | AQ32: Uzebekistan | AR32: =Results!$O$55 -> -2 | AS32: 1 | AT32: =AR32*AS32 -> -2 | AU32: Ghana | AV32: =Results!$O$60 -> 6 | AW32: 2 | AX32: =AV32*AW32 -> 12
A33: Norway | B33: =Results!$O$46 -> 12 | C33: 3 | D33: =B33*C33 -> 36 | E33: Jordan | F33: =Results!$O$51 -> -1 | G33: 1 | H33: =F33*G33 -> -1 | I33: Colombia | J33: =Results!$O$56 -> 9 | K33: 2 | L33: =J33*K33 -> 18 | M33: Panama | N33: =Results!$O$61 -> -3 | O33: 1 | P33: =N33*O33 -> -3 | R33: Norway | S33: =Results!$O$46 -> 12 | T33: 2 | U33: =S33*T33 -> 24 | V33: Jordan | W33: =Results!$O$51 -> -1 | X33: 1 | Y33: =W33*X33 -> -1 | Z33: Colombia | AA33: =Results!$O$56 -> 9 | AB33: 2 | AC33: =AA33*AB33 -> 18 | AD33: Panama | AE33: =Results!$O$61 -> -3 | AG33: =AE33*AF33 -> 0 | AI33: Norway | AJ33: =Results!$O$46 -> 12 | AK33: 2 | AL33: =AJ33*AK33 -> 24 | AM33: Jordan | AN33: =Results!$O$51 -> -1 | AP33: =AN33*AO33 -> 0 | AQ33: Colombia | AR33: =Results!$O$56 -> 9 | AS33: 2 | AT33: =AR33*AS33 -> 18 | AU33: Panama | AV33: =Results!$O$61 -> -3 | AW33: 1 | AX33: =AV33*AW33 -> -3
A35: Name: | B35: Kevin Lippy (P) | M35: Total: | N35: =SUM(D37:D40,D42:D45,H37:H40, H42:H45,L37:L40,L42:L45,P37:P40,P42:P45,D47:D50,H47:H50,L47:L50,P47:P50) -> 375 | R35: Name: | S35: Josh Luff (P) | AD35: Total: | AE35: =SUM(U37:U40,U42:U45,Y37:Y40, Y42:Y45,AC37:AC40,AC42:AC45,AG37:AG40,AG42:AG45,U47:U50,Y47:Y50,AC47:AC50,AG47:AG50) -> 317 | AI35: Name: | AJ35: Ivan Fuchs (P) | AU35: Total: | AV35: =SUM(AL37:AL40,AL42:AL45,AP37:AP40, AP42:AP45,AT37:AT40,AT42:AT45,AX37:AX40,AX42:AX45,AL47:AL50,AP47:AP50,AT47:AT50,AX47:AX50) -> 363
A36: Group A | B36: Score | C36: Multiplier | D36: Points | E36: Group B | F36: Score | G36: Multiplier | H36: Points | I36: Group C | J36: Score | K36: Multiplier | L36: Points | M36: Group D | N36: Score | O36: Multiplier | P36: Points | R36: Group A | S36: Score | T36: Multiplier | U36: Points | V36: Group B | W36: Score | X36: Multiplier | Y36: Points | Z36: Group C | AA36: Score | AB36: Multiplier | AC36: Points | AD36: Group D | AE36: Score | AF36: Multiplier | AG36: Points | AI36: Group A | AJ36: Score | AK36: Multiplier | AL36: Points | AM36: Group B | AN36: Score | AO36: Multiplier | AP36: Points | AQ36: Group C | AR36: Score | AS36: Multiplier | AT36: Points | AU36: Group D | AV36: Score | AW36: Multiplier | AX36: Points
A37: Mexico | B37: =Results!$O$3 -> 3 | C37: 3 | D37: =B37*C37 -> 9 | E37: Canada | F37: =Results!$O$8 -> 2 | G37: 2 | H37: =F37*G37 -> 4 | I37: Brazil | J37: =Results!$O$13 -> 2 | K37: 3 | L37: =J37*K37 -> 6 | M37: USA | N37: =Results!$O$18 -> 11 | O37: 3 | P37: =N37*O37 -> 33 | R37: Mexico | S37: =Results!$O$3 -> 3 | T37: 3 | U37: =S37*T37 -> 9 | V37: Canada | W37: =Results!$O$8 -> 2 | X37: 2 | Y37: =W37*X37 -> 4 | Z37: Brazil | AA37: =Results!$O$13 -> 2 | AB37: 3 | AC37: =AA37*AB37 -> 6 | AD37: USA | AE37: =Results!$O$18 -> 11 | AF37: 1 | AG37: =AE37*AF37 -> 11 | AI37: Mexico | AJ37: =Results!$O$3 -> 3 | AK37: 3 | AL37: =AJ37*AK37 -> 9 | AM37: Canada | AN37: =Results!$O$8 -> 2 | AO37: 2 | AP37: =AN37*AO37 -> 4 | AQ37: Brazil | AR37: =Results!$O$13 -> 2 | AS37: 3 | AT37: =AR37*AS37 -> 6 | AU37: USA | AV37: =Results!$O$18 -> 11 | AW37: 3 | AX37: =AV37*AW37 -> 33
A38: Sth Africa | B38: =Results!$O$4 -> -14 | D38: =B38*C38 -> 0 | E38: Bosnia | F38: =Results!$O$9 -> 1 | G38: 1 | H38: =F38*G38 -> 1 | I38: Morocco | J38: =Results!$O$14 -> 4 | K38: 2 | L38: =J38*K38 -> 8 | M38: Paraguay | N38: =Results!$O$19 -> -7 | O38: 1 | P38: =N38*O38 -> -7 | R38: Sth Africa | S38: =Results!$O$4 -> -14 | T38: 1 | U38: =S38*T38 -> -14 | V38: Bosnia | W38: =Results!$O$9 -> 1 | X38: 1 | Y38: =W38*X38 -> 1 | Z38: Morocco | AA38: =Results!$O$14 -> 4 | AB38: 1 | AC38: =AA38*AB38 -> 4 | AD38: Paraguay | AE38: =Results!$O$19 -> -7 | AF38: 3 | AG38: =AE38*AF38 -> -21 | AI38: Sth Africa | AJ38: =Results!$O$4 -> -14 | AL38: =AJ38*AK38 -> 0 | AM38: Bosnia | AN38: =Results!$O$9 -> 1 | AP38: =AN38*AO38 -> 0 | AQ38: Morocco | AR38: =Results!$O$14 -> 4 | AS38: 2 | AT38: =AR38*AS38 -> 8 | AU38: Paraguay | AV38: =Results!$O$19 -> -7 | AW38: 2 | AX38: =AV38*AW38 -> -14
A39: Korea Rep | B39: =Results!$O$5 -> 7 | C39: 1 | D39: =B39*C39 -> 7 | E39: Qatar | F39: =Results!$O$10 -> 2 | H39: =F39*G39 -> 0 | I39: Haiti | J39: =Results!$O$15 -> -2 | L39: =J39*K39 -> 0 | M39: Australia | N39: =Results!$O$20 -> 9 | P39: =N39*O39 -> 0 | R39: Korea Rep | S39: =Results!$O$5 -> 7 | T39: 2 | U39: =S39*T39 -> 14 | V39: Qatar | W39: =Results!$O$10 -> 2 | Y39: =W39*X39 -> 0 | Z39: Haiti | AA39: =Results!$O$15 -> -2 | AC39: =AA39*AB39 -> 0 | AD39: Australia | AE39: =Results!$O$20 -> 9 | AG39: =AE39*AF39 -> 0 | AI39: Korea Rep | AJ39: =Results!$O$5 -> 7 | AK39: 1 | AL39: =AJ39*AK39 -> 7 | AM39: Qatar | AN39: =Results!$O$10 -> 2 | AO39: 1 | AP39: =AN39*AO39 -> 2 | AQ39: Haiti | AR39: =Results!$O$15 -> -2 | AT39: =AR39*AS39 -> 0 | AU39: Australia | AV39: =Results!$O$20 -> 9 | AX39: =AV39*AW39 -> 0
A40: Czechia | B40: =Results!$O$6 -> 0 | C40: 2 | D40: =B40*C40 -> 0 | E40: Switzerland | F40: =Results!$O$11 -> 3 | G40: 3 | H40: =F40*G40 -> 9 | I40: Scotland | J40: =Results!$O$16 -> 4 | K40: 1 | L40: =J40*K40 -> 4 | M40: Turkey | N40: =Results!$O$21 -> -3 | O40: 2 | P40: =N40*O40 -> -6 | R40: Czechia | S40: =Results!$O$6 -> 0 | U40: =S40*T40 -> 0 | V40: Switzerland | W40: =Results!$O$11 -> 3 | X40: 3 | Y40: =W40*X40 -> 9 | Z40: Scotland | AA40: =Results!$O$16 -> 4 | AB40: 2 | AC40: =AA40*AB40 -> 8 | AD40: Turkey | AE40: =Results!$O$21 -> -3 | AF40: 2 | AG40: =AE40*AF40 -> -6 | AI40: Czechia | AJ40: =Results!$O$6 -> 0 | AK40: 2 | AL40: =AJ40*AK40 -> 0 | AM40: Switzerland | AN40: =Results!$O$11 -> 3 | AO40: 3 | AP40: =AN40*AO40 -> 9 | AQ40: Scotland | AR40: =Results!$O$16 -> 4 | AS40: 1 | AT40: =AR40*AS40 -> 4 | AU40: Turkey | AV40: =Results!$O$21 -> -3 | AW40: 1 | AX40: =AV40*AW40 -> -3
A41: Group E | B41: Score | C41: Multiplier | D41: Points | E41: Group F | F41: Score | G41: Multiplier | H41: Points | I41: Group G | J41: Score | K41: Multiplier | L41: Points | M41: Group H | N41: Score | O41: Multiplier | P41: Points | R41: Group E | S41: Score | T41: Multiplier | U41: Points | V41: Group F | W41: Score | X41: Multiplier | Y41: Points | Z41: Group G | AA41: Score | AB41: Multiplier | AC41: Points | AD41: Group H | AE41: Score | AF41: Multiplier | AG41: Points | AI41: Group E | AJ41: Score | AK41: Multiplier | AL41: Points | AM41: Group F | AN41: Score | AO41: Multiplier | AP41: Points | AQ41: Group G | AR41: Score | AS41: Multiplier | AT41: Points | AU41: Group H | AV41: Score | AW41: Multiplier | AX41: Points
A42: Germany | B42: =Results!$O$23 -> 18 | C42: 5 | D42: =B42*C42 -> 90 | E42: Netherlands | F42: =Results!$O$28 -> 2 | G42: 3 | H42: =F42*G42 -> 6 | I42: Belgium | J42: =Results!$O$33 -> 2 | K42: 3 | L42: =J42*K42 -> 6 | M42: Spain | N42: =Results!$O$38 -> 2 | O42: 3 | P42: =N42*O42 -> 6 | R42: Germany | S42: =Results!$O$23 -> 18 | T42: 3 | U42: =S42*T42 -> 54 | V42: Netherlands | W42: =Results!$O$28 -> 2 | X42: 2 | Y42: =W42*X42 -> 4 | Z42: Belgium | AA42: =Results!$O$33 -> 2 | AB42: 3 | AC42: =AA42*AB42 -> 6 | AD42: Spain | AE42: =Results!$O$38 -> 2 | AF42: 3 | AG42: =AE42*AF42 -> 6 | AI42: Germany | AJ42: =Results!$O$23 -> 18 | AK42: 3 | AL42: =AJ42*AK42 -> 54 | AM42: Netherlands | AN42: =Results!$O$28 -> 2 | AO42: 3 | AP42: =AN42*AO42 -> 6 | AQ42: Belgium | AR42: =Results!$O$33 -> 2 | AS42: 3 | AT42: =AR42*AS42 -> 6 | AU42: Spain | AV42: =Results!$O$38 -> 2 | AW42: 3 | AX42: =AV42*AW42 -> 6
...

Sheet Ladder
A1: # | B1: Name | C1: Total Points | D1: * Selected
A2: 1 | B2: =Entries!$AJ$205 -> Teddy Rooks (P) | C2: =Entries!$AV$205 -> 418 | D2: Netherlands
A3: 2 | B3: =Entries!$B$103 -> Michael Orford (P) | C3: =Entries!$N$103 -> 417 | D3: France
A4: 3 | B4: =Entries!$AJ$307 -> Craig Ring (P) | C4: =Entries!$AV$307 -> 415 | D4: France
A5: 4 | B5: =Entries!$S$69 -> Ray Boggiano (P) | C5: =Entries!$AE$69 -> 414 | D5: France
A6: 5 | B6: =Entries!$AJ$120 -> Danny Dresner (P) | C6: =Entries!$AV$120 -> 406 | D6: Germany
A7: 6 | B7: =Entries!$B$18 -> Nash Dresner (P) | C7: =Entries!$N$18 -> 403 | D7: England
A8: 7 | B8: =Entries!$B$273 -> Dan Segal (P) | C8: =Entries!$N$273 -> 401 | D8: Germany
A9: 8 | B9: =Entries!$S$324 -> Syrus Wynne | C9: =Entries!$AE$324 -> 401 | D9: Spain
A10: 9 | B10: =Entries!$S$86 -> Liam Gerathy (P) | C10: =Entries!$AE$86 -> 399 | D10: France
A11: 10 | B11: =Entries!$AJ$188 -> Liron Rutovitz (P) | C11: =Entries!$AV$188 -> 398 | D11: France
A12: 11 | B12: =Entries!$B$1 -> Lennon Dresner (P) | C12: =Entries!$N$1 -> 394 | D12: Brazil
A13: 12 | B13: =Entries!$S$52 -> Clive Baskin (P) | C13: =Entries!$AE$52 -> 393 | D13: France
A14: 13 | B14: =Entries!$B$137 -> Robbie Baskin (P) | C14: =Entries!$N$137 -> 389 | D14: France
A15: 14 | B15: =Entries!$S$154 -> Josie Rutovitz (P) | C15: =Entries!$AE$154 -> 388 | D15: Spain
A16: 15 | B16: =Entries!$B$222 -> Matthew Bozic (P) | C16: =Entries!$N$222 -> 388 | D16: Spain
A17: 16 | B17: =Entries!$AJ$18 -> Gavin Fuchs (P) | C17: =Entries!$AV$18 -> 382 | D17: England
A18: 17 | B18: =Entries!$AJ$69 -> David Vince Smith (P) | C18: =Entries!$AV$69 -> 382 | D18: England
A19: 18 | B19: =Entries!$AJ$52 -> Laine Poirier (P) | C19: =Entries!$AV$52 -> 382 | D19: France
A20: 19 | B20: =Entries!$S$18 -> Max Maike (P) | C20: =Entries!$AE$18 -> 378 | D20: Germany
A21: 20 | B21: =Entries!$B$154 -> Tali Hollis (P) | C21: =Entries!$N$154 -> 377 | D21: France
A22: 21 | B22: =Entries!$B$239 -> Paul Selikman (P) | C22: =Entries!$N$239 -> 376 | D22: Spain
A23: 22 | B23: =Entries!$B$35 -> Kevin Lippy (P) | C23: =Entries!$N$35 -> 375 | D23: Germany
A24: 23 | B24: =Entries!$B$69 -> Paul Mooney | C24: =Entries!$N$69 -> 374 | D24: Mexico
A25: 24 | B25: =Entries!$S$120 -> Rory Gallagher (P) | C25: =Entries!$AE$120 -> 374 | D25: France
A26: 25 | B26: =Entries!$AJ$1 -> Tyler & Mark Hall | C26: =Entries!$AV$1 -> 373 | D26: France
A27: 26 | B27: =Entries!$S$188 -> Edward Shmidt (P) | C27: =Entries!$AE$188 -> 372 | D27: England
A28: 27 | B28: =Entries!$B$171 -> Adam Horwitz (P) | C28: =Entries!$N$171 -> 372 | D28: England
A29: 28 | B29: =Entries!$AJ$290 -> Tobias Morgan (P) | C29: =Entries!$AV$290 -> 371 | D29: France
A30: 29 | B30: =Entries!$B$205 -> Benjamin Powell (P) | C30: =Entries!$N$205 -> 370 | D30: England
A31: 30 | B31: =Entries!$B$188 -> Jenna Baskin (P) | C31: =Entries!$N$188 -> 369 | D31: Spain
A32: 31 | B32: =Entries!$S$273 -> Carl Seubert (P) | C32: =Entries!$AE$273 -> 369 | D32: France
A33: 32 | B33: =Entries!$S$239 -> Romi Rutovitz (P) | C33: =Entries!$AE$239 -> 369 | D33: France
A34: 33 | B34: =Entries!$B$52 -> Alon Beran (P) | C34: =Entries!$N$52 -> 368 | D34: Spain
A35: 34 | B35: =Entries!$S$290 -> Bryan Resnik (P) | C35: =Entries!$AE$290 -> 367 | D35: Brazil
A36: 35 | B36: =Entries!$B$290 -> Jarred Rubin (P) | C36: =Entries!$N$290 -> 367 | D36: Spain
A37: 36 | B37: =Entries!$B$256 -> Mitchell James (P) | C37: =Entries!$N$256 -> 366 | D37: Brazil
A38: 37 | B38: =Entries!$AJ$324 -> Micheal O'Brien (P) | C38: =Entries!$AV$324 -> 366 | D38: France
A39: 38 | B39: =Entries!$S$307 -> Sean Eichholz (P) | C39: =Entries!$AE$307 -> 364 | D39: Netherlands
A40: 39 | B40: =Entries!$AJ$103 -> Marc Cohen (P) | C40: =Entries!$AV$103 -> 364 | D40: France
...
